<?xml version="1.0"?>

<robot xmlns="http://www.ros.org/wiki/xacro" xmlns:xacro="http://www.ros.org/wiki/xacro" name="arduinobot">

    <!-- Start GZ or Ignition depending on ROS 2 Version -->
    <xacro:arg name="is_ignition" default="true"/>

    <!-- Load Simulated or Real Hardware Interfaces -->
    <xacro:arg name="is_sim" default="true"/>

    <!-- Include Gazebo Parameters --> 
    <xacro:include filename="$(find arduinobot_description)/urdf/arduinobot_gazebo.xacro" />

    <!-- Include ros2_control Plugins -->
    <xacro:include filename="$(find arduinobot_description)/urdf/arduinobot_ros2_control.xacro" />

  <xacro:property name="PI" value="3.14159265359"/>
  <xacro:property name="effort" value="30.0"/>
  <xacro:property name="velocity" value="10.0"/>

  <xacro:macro name="default_inertial" params="mass">
        <inertial>
            <origin xyz="0 0 0" rpy="0 0 0"/>
            <mass value="${mass}" />
            <inertia ixx="1.0" ixy="0.0" ixz="0.0"
                     iyy="1.0" iyz="0.0"
                     izz="1.0" />
        </inertial>
  </xacro:macro>

  <link name="world"/>

  <link name="base_link">
    <xacro:default_inertial mass="1.0"/>
    <visual>
      <origin xyz="-0.5 -0.5 0" rpy="0 0 0"/>
      <geometry>
        <mesh filename="package://arduinobot_description/meshes/basement.STL" scale="0.01 0.01 0.01"/>
      </geometry>     
    </visual>
    <collision>
      <origin xyz="-0.5 -0.5 0" rpy="0 0 0"/>
      <geometry>
        <mesh filename="package://arduinobot_description/meshes/basement.STL" scale="0.01 0.01 0.01"/>
      </geometry> 
    </collision>
  </link>


  <link name="base_plate">
    <xacro:default_inertial mass="0.1"/>
    <visual>
      <origin xyz="-0.39 -0.39 -0.56" rpy="0 0 0"/>
      <geometry>
        <mesh filename="package://arduinobot_description/meshes/base_plate.STL" scale="0.01 0.01 0.01"/>
      </geometry>
    </visual>
    <collision>
      <origin xyz="-0.39 -0.39 -0.56" rpy="0 0 0"/>
      <geometry>
        <mesh filename="package://arduinobot_description/meshes/base_plate.STL" scale="0.01 0.01 0.01"/>
      </geometry>
    </collision>
  </link>


  <link name="forward_drive_arm">
    <xacro:default_inertial mass="0.1"/>
    <visual>
      <origin xyz="0.19 0.06 -0.08" rpy="0 -${PI/2} ${PI/2}"/>
      <geometry>
        <mesh filename="package://arduinobot_description/meshes/forward_drive_arm.STL" scale="0.01 0.01 0.01"/>
      </geometry>
      <collision>
        <origin xyz="0.19 0.06 -0.08" rpy="0 -${PI/2} ${PI/2}"/>
        <geometry>
          <mesh filename="package://arduinobot_description/meshes/forward_drive_arm.STL" scale="0.01 0.01 0.01"/>
        </geometry>
      </collision>
    </visual>
  </link>


  <link name="horizontal_arm">
    <xacro:default_inertial mass="0.1"/>
    <visual>
      <origin xyz="-0.03 -0.4 -0.06" rpy="${PI/2} 0 ${PI/2}"/>
      <geometry>
        <mesh filename="package://arduinobot_description/meshes/horizontal_arm.STL" scale="0.01 0.01 0.01"/>
      </geometry>
      <collision>
        <origin xyz="-0.03 -0.4 -0.06" rpy="${PI/2} 0 ${PI/2}"/>
        <geometry>
          <mesh filename="package://arduinobot_description/meshes/horizontal_arm.STL" scale="0.01 0.01 0.01"/>
        </geometry>
      </collision>
    </visual>
  </link>

  <link name="claw_support">
    <xacro:default_inertial mass="0.05"/>
    <visual>
      <origin xyz="0 -0.05 -0.15" rpy="0 0 ${PI/2}"/>
      <geometry>
        <mesh filename="package://arduinobot_description/meshes/claw_support.STL" scale="0.01 0.01 0.01"/>
      </geometry>
    </visual>
    <collision>
      <origin xyz="0 -0.05 -0.15" rpy="0 0 ${PI/2}"/>
      <geometry>
        <mesh filename="package://arduinobot_description/meshes/claw_support.STL" scale="0.01 0.01 0.01"/>
      </geometry>
    </collision>
  </link>

  <link name="gripper_left">
    <xacro:default_inertial mass="0.01"/>
    <visual>
      <origin xyz="-0.04 0.5 -0.1" rpy="0 0 -${PI/2}"/>
      <geometry>
        <mesh filename="package://arduinobot_description/meshes/left_finger.STL" scale="0.01 0.01 0.01"/>
      </geometry>
    </visual>
    <collision>
      <origin xyz="-0.04 0.5 -0.1" rpy="0 0 -${PI/2}"/>
      <geometry>
        <mesh filename="package://arduinobot_description/meshes/left_finger.STL" scale="0.01 0.01 0.01"/>
      </geometry>
    </collision>
  </link>


  <link name="gripper_right">
    <xacro:default_inertial mass="0.01"/>
    <visual>
      <origin xyz="-0.1 0.5 -0.1" rpy="0 0 -${PI/2}"/>
      <geometry>
        <mesh filename="package://arduinobot_description/meshes/right_finger.STL" scale="0.01 0.01 0.01"/>
      </geometry>
    </visual>
    <collision>
      <origin xyz="-0.1 0.5 -0.1" rpy="0 0 -${PI/2}"/>
      <geometry>
        <mesh filename="package://arduinobot_description/meshes/right_finger.STL" scale="0.01 0.01 0.01"/>
      </geometry>
    </collision>
  </link>
  <link name="rgb_camera">
      <xacro:default_inertial mass="0.001"/>
      <visual>
            <origin rpy="-1.57 0 -1.57" xyz="-0.1 0.125 0.15"/>
            <geometry>
                <mesh filename="package://arduinobot_description/meshes/pi_camera.STL" scale="0.01 0.01 0.01"/>
            </geometry>
      </visual>
      <collision>
            <origin rpy="-1.57 0 -1.57" xyz="-0.1 0.125 0.15"/>
            <geometry>
                <mesh filename="package://arduinobot_description/meshes/pi_camera.STL" scale="0.01 0.01 0.01"/>
            </geometry>
      </collision>
  </link>

  <joint name="virtual_joint" type="fixed">
    <origin xyz="0 0 0" rpy="0 0 0"/>
    <parent link="world"/>
    <child link="base_link"/>
  </joint>



  <joint name="joint_1" type="revolute">
    <axis xyz="0 0 1"/>
    <origin xyz="0 0 0.307" rpy="0 0 0"/>
    <parent link="base_link"/>
    <child link="base_plate"/>
    <limit lower="-${PI/2}" upper="${PI/2}" effort="${effort}" velocity="${velocity}"/>
  </joint> 

  <joint name="joint_2" type="revolute">
    <axis xyz="1 0 0"/>
    <origin xyz="-0.02 0 0.35" rpy="0 0 0"/>
    <parent link="base_plate"/>
    <child link="forward_drive_arm"/>
    <limit lower="-${PI/2}" upper="${PI/2}" effort="${effort}" velocity="${velocity}"/>
  </joint>



  <joint name="joint_3" type="revolute">
    <axis xyz="1 0 0"/>
    <origin xyz="0 0 0.8" rpy="0 0 0"/>
    <parent link="forward_drive_arm"/>
    <child link="horizontal_arm"/>
    <limit lower="-${PI/2}" upper="${PI/2}" effort="${effort}" velocity="${velocity}"/>
  </joint>


  <joint name="joint_4" type="fixed">
    <origin xyz="0 0.82 0" rpy="0 0 0"/>
    <parent link="horizontal_arm"/>
    <child link="claw_support"/>
  </joint>




  <joint name="joint_5" type="revolute">
    <axis xyz="0 0 1"/>
    <origin xyz="-0.04 0.13 -0.1" rpy="0 0 0"/>
    <parent link="claw_support"/>
    <child link="gripper_right"/>
    <limit lower="-${PI/2}" upper="0.0" effort="${effort}" velocity="${velocity}"/>
  </joint>

  <joint name="joint_6" type="revolute">
    <axis xyz="0 0 1"/>
    <origin xyz="-0.22 0.13 -0.1" rpy="0 0 0"/>
    <parent link="claw_support"/>
    <child link="gripper_left"/>
    
    <limit lower="0.0" upper="${PI/2}" effort="${effort}" velocity="${velocity}"/>
    <minic joint="joint_5" multiplier="-1"/>
  </joint>

  <joint name ="rgb_camera_joint" type="fixed">
        <parent link="base_link"/>
        <child link = "rgb_camera"/>
        <origin xyz="0 0.45 0.2" rpy="0 -0.5 1.57"/>
  </joint>


</robot>